Workbook

Sheet Sheet1
BG2: HZE-tau | BH2: X-tau | BI2: Bgd
A4: B6C3 | B4: =B23 -> 1.6428571 | C4: =C23 -> 1 | D4: =D23 -> 2.0833333 | E4: =E23 -> 1 | F4: =F23 -> 0 | H4: =H23 -> 1.625 | I4: =I23 -> 13.157895 | K4: =K23 -> 1 | L4: =L23 -> 1.6666667 | N4: =N23 -> 1 | P4: =P23 -> 4.4285714 | Q4: =Q23 -> 1 | R4: =R23 -> 8.6 | S4: =S23 -> 2.5 | T4: =T23 -> 1.1533333 | U4: =U23 -> 1 | V4: =V23 -> 2 | W4: =W23 -> 1 | Y4: =Y23 -> 1.4 | AA4: =AA23 -> 0.915 | AE4: =AE23 -> 2.93125 | AF4: =AF23 -> 14 | AI4: =AI23 -> 1.5 | AJ4: =AJ23 -> 0 | AK4: =AK23 -> 1 | AL4: =AL23 -> 1.1333333 | AM4: =AM23 -> 0.625 | AO4: =AO23 -> 1.03 | AQ4: =AQ23 -> 9.3 | AR4: =AR23 -> 1 | AS4: =AS23 -> 2 | AT4: =AT23 -> 0.75 | AU4: =AU23 -> 3.4375 | AV4: =AV23 -> 1.2809524 | AW4: =AW23 -> 0.275 | AX4: =AX23 -> 0.86363636 | AZ4: =AZ23 -> 5.745 | BA4: =BA23 -> 0.75 | BC4: =BC23 -> 1 | BE4: =AVERAGE(B4:BD4) -> 2.4819059 | BF4: B6C3 | BG4: 11.250761 | BH4: 3.93276 | BI4: 0.3852915
A5: BALB/C | B5: 5 | D5: 5 | F5: 5 | H5: 2.5 | I5: 15 | J5: 2.5 | K5: 2.5 | L5: 2.5 | M5: 2.5 | N5: 1 | O5: 2.5 | P5: 35 | R5: 5 | S5: 5 | T5: 35 | V5: 15 | W5: 2.5 | X5: 20 | Y5: 20 | Z5: 2.5 | AA5: 5 | AC5: 0 | AE5: 65 | AF5: 2.5 | AG5: 35 | AI5: 2.5 | AJ5: 0 | AK5: 5 | AL5: 2.5 | AO5: 0 | AQ5: 65 | AS5: 2.5 | AT5: 0 | AU5: 5 | AV5: 2.5 | AX5: 15 | AY5: 5 | AZ5: 15 | BA5: 65 | BC5: 0 | BD5: 0 | BE5: =AVERAGE(B5:BD5) -> 11.670732 | BF5: BALBC | BG5: 11.55611 | BH5: 3.8970483 | BI5: 0.4243104
A6: CBA | B6: 5 | D6: 5 | H6: 1 | I6: 90 | L6: 5 | M6: 5 | N6: 1 | P6: 5 | R6: 5 | S6: 5 | T6: 35 | V6: 5 | W6: 5 | X6: 0 | Y6: 65 | Z6: 0 | AA6: 5 | AC6: 0 | AE6: 15 | AG6: 15 | AI6: 5 | AJ6: 0 | AL6: 0 | AO6: 2.5 | AQ6: 35 | AT6: 1 | AU6: 5 | AV6: 5 | AX6: 5 | AY6: 2.5 | AZ6: 15 | BA6: 5 | BC6: 0 | BD6: 0 | BE6: =AVERAGE(B6:BD6) -> 10.382353 | BF6: CBA | BG6: 13.130422 | BH6: 4.254018 | BI6: 0.514662
A7: C3H | B7: 5 | D7: 0 | H7: 15 | I7: 90 | L7: 0 | M7: 5 | N7: 2.5 | P7: 65 | R7: 2.5 | S7: 2.5 | T7: 5 | V7: 0 | W7: 2.5 | X7: 0 | Y7: 90 | Z7: 0 | AA7: 2.5 | AC7: 0 | AE7: 90 | AJ7: 0 | AL7: 0 | AO7: 0 | AP7: 2.5 | AQ7: 35 | AS7: 2.5 | AT7: 2.5 | AU7: 2.5 | AV7: 5 | AX7: 2.5 | AY7: 2.5 | AZ7: 5 | BA7: 0 | BB7: 2.5 | BC7: 2.5 | BD7: 0 | BE7: =AVERAGE(B7:BD7) -> 12.642857 | BF7: C3H | BG7: 13.397734 | BH7: 4.1423303 | BI7: 0.4294885
A8: C57BL/6 | B8: 5 | D8: 5 | E8: 5 | F8: 0 | G8: 2.5 | H8: 5 | I8: 35 | L8: 0 | N8: 15 | P8: 5 | Q8: 5 | R8: 90 | S8: 35 | T8: 5 | U8: 0 | V8: 15 | W8: 5 | X8: 0 | Y8: 5 | Z8: 2.5 | AA8: 15 | AB8: 15 | AC8: 0 | AD8: 2.5 | AE8: 65 | AF8: 1 | AH8: 0 | AI8: 5 | AJ8: 2.5 | AL8: 5 | AM8: 0 | AN8: 2.5 | AO8: 0 | AP8: 5 | AQ8: 15 | AR8: 5 | AS8: 5 | AT8: 2.5 | AU8: 5 | AV8: 5 | AW8: 2.5 | AX8: 5 | AY8: 1 | AZ8: 5 | BA8: 5 | BC8: 5 | BD8: 2.5 | BE8: =AVERAGE(B8:BD8) -> 8.9787234 | BF8: C57 | BG8: 11.248485 | BH8: 3.8284658 | BI8: 0.386223
A9: Pearson-HZE | B9: =PEARSON(B4:B8,$BG4:$BG8) -> 0.45707272 | D9: =PEARSON(D4:D8,$BG4:$BG8) -> -0.39993999 | H9: =PEARSON(H4:H8,$BG4:$BG8) -> 0.5341556 | I9: =PEARSON(I4:I8,$BG4:$BG8) -> 0.95301915 | L9: =PEARSON(L4:L8,$BG4:$BG8) -> 0.25299326 | N9: =PEARSON(N4:N8,$BG4:$BG8) -> -0.39421288 | P9: =PEARSON(P4:P8,$BG4:$BG8) -> 0.53065862 | R9: =PEARSON(R4:R8,$BG4:$BG8) -> -0.49831497 | S9: =PEARSON(S4:S8,$BG4:$BG8) -> -0.45565197 | T9: =PEARSON(T4:T8,$BG4:$BG8) -> 0.23219916 | V9: =PEARSON(V4:V8,$BG4:$BG8) -> -0.59637875 | W9: =PEARSON(W4:W8,$BG4:$BG8) -> 0.22381797 | Y9: =PEARSON(Y4:Y8,$BG4:$BG8) -> 0.98815527 | AA9: =PEARSON(AA4:AA8,$BG4:$BG8) -> -0.3588474 | AE9: =PEARSON(AE4:AE8,$BG4:$BG8) -> 0.22415433 | AJ9: =PEARSON(AJ4:AJ8,$BG4:$BG8) -> -0.45827403 | AL9: =PEARSON(AL4:AL8,$BG4:$BG8) -> -0.75608644 | AO9: =PEARSON(AO4:AO8,$BG4:$BG8) -> 0.35322357 | AQ9: =PEARSON(AQ5:AQ8,$BG5:$BG8) -> -0.024056496 | AT9: =PEARSON(AT4:AT8,$BG4:$BG8) -> 0.29629056 | AU9: =PEARSON(AU4:AU8,$BG4:$BG8) -> -0.37608609 | AV9: =PEARSON(AV4:AV8,$BG4:$BG8) -> 0.62101874 | AX9: =PEARSON(AX4:AX8,$BG4:$BG8) -> -0.22423315 | AZ9: =PEARSON(AZ4:AZ8,$BG4:$BG8) -> 0.17147007 | BA9: =PEARSON(BA4:BA8,$BG4:$BG8) -> -0.30693152 | BC9: =PEARSON(BC4:BC8,$BG4:$BG8) -> -0.22429872 | BE9: =PEARSON(BE5:BE8,$BG5:$BG8) -> 0.56410623
A10: Pearson-X | B10: =PEARSON(B4:B8,$BH4:$BH8) -> 0.24356984 | D10: =PEARSON(D4:D8,$BH4:$BH8) -> -0.26112247 | H10: =PEARSON(H4:H8,$BH4:$BH8) -> 0.21462123 | I10: =PEARSON(I4:I8,$BH4:$BH8) -> 0.88466444 | L10: =PEARSON(L4:L8,$BH4:$BH8) -> 0.53762256 | N10: =PEARSON(N4:N8,$BH4:$BH8) -> -0.53609455 | P10: =PEARSON(P4:P8,$BH4:$BH8) -> 0.23352701 | R10: =PEARSON(R4:R8,$BH4:$BH8) -> -0.5918669 | S10: =PEARSON(S4:S8,$BH4:$BH8) -> -0.55687007 | T10: =PEARSON(T4:T8,$BH4:$BH8) -> 0.33832874 | V10: =PEARSON(V4:V8,$BH4:$BH8) -> -0.65878329 | W10: =PEARSON(W4:W8,$BH4:$BH8) -> 0.21364383 | Y10: =PEARSON(Y4:Y8,$BH4:$BH8) -> 0.86318179 | AA10: =PEARSON(AA4:AA8,$BH4:$BH8) -> -0.46540253 | AE10: =PEARSON(AE4:AE8,$BH4:$BH8) -> -0.15153576 | AJ10: =PEARSON(AJ4:AJ8,$BH4:$BH8) -> -0.56856312 | AL10: =PEARSON(AL4:AL8,$BH4:$BH8) -> -0.85341232 | AO10: =PEARSON(AO4:AO8,$BH4:$BH8) -> 0.66940469 | AQ10: =PEARSON(AQ5:AQ8,$BH5:$BH8) -> 0.0030161494 | AT10: =PEARSON(AT4:AT8,$BH4:$BH8) -> 0.071202517 | AU10: =PEARSON(AU4:AU8,$BH4:$BH8) -> -0.24774941 | AV10: =PEARSON(AV4:AV8,$BH4:$BH8) -> 0.4564115 | AX10: =PEARSON(AX4:AX8,$BH4:$BH8) -> -0.28973683 | AZ10: =PEARSON(AZ4:AZ8,$BH4:$BH8) -> 0.321426 | BA10: =PEARSON(BA4:BA8,$BH4:$BH8) -> -0.35668477 | BC10: =PEARSON(BC4:BC8,$BH4:$BH8) -> -0.4372904 | BE10: =PEARSON(BE5:BE8,$BH5:$BH8) -> 0.38022952
A11: Bgd | B11: =PEARSON(B4:B8,$BI4:$BI8) -> 0.45325911 | D11: =PEARSON(D4:D8,$BI4:$BI8) -> 0.24272042 | H11: =PEARSON(H4:H8,$BI4:$BI8) -> -0.14650455 | I11: =PEARSON(I4:I8,$BI4:$BI8) -> 0.71774496 | L11: =PEARSON(L4:L8,$BI4:$BI8) -> 0.80741381 | N11: =PEARSON(N4:N8,$BI4:$BI8) -> -0.45127331 | P11: =PEARSON(P4:P8,$BI4:$BI8) -> 0.00061108332 | R11: =PEARSON(R4:R8,$BI4:$BI8) -> -0.46377523 | S11: =PEARSON(S4:S8,$BI4:$BI8) -> -0.38909132 | T11: =PEARSON(T4:T8,$BI4:$BI8) -> 0.73211592 | V11: =PEARSON(V4:V8,$BI4:$BI8) -> -0.22130242 | W11: =PEARSON(W4:W8,$BI4:$BI8) -> 0.47720882 | Y11: =PEARSON(Y4:Y8,$BI4:$BI8) -> 0.65567843 | AA11: =PEARSON(AA4:AA8,$BI4:$BI8) -> -0.2135305 | AE11: =PEARSON(AE4:AE8,$BI4:$BI8) -> -0.21137966 | AJ11: =PEARSON(AJ4:AJ8,$BI4:$BI8) -> -0.4433721 | AL11: =PEARSON(AL4:AL8,$BI4:$BI8) -> -0.60253003 | AO11: =PEARSON(AO4:AO8,$BI4:$BI8) -> 0.74680982 | AQ11: =PEARSON(AQ4:AQ8,$BI4:$BI8) -> 0.39574442 | AT11: =PEARSON(AT4:AT8,$BI4:$BI8) -> -0.1965279 | AU11: =PEARSON(AU4:AU8,$BI4:$BI8) -> 0.25756377 | AV11: =PEARSON(AV4:AV8,$BI4:$BI8) -> 0.45399032 | AX11: =PEARSON(AX4:AX8,$BI4:$BI8) -> 0.11737689 | AZ11: =PEARSON(AZ4:AZ8,$BI4:$BI8) -> 0.70804717 | BA11: =PEARSON(BA4:BA8,$BI4:$BI8) -> -0.0079878134 | BC11: =PEARSON(BC4:BC8,$BI4:$BI8) -> -0.55766307
A12: "Very High" - includes frequencies reported in the literature as being between >80% and 100% as well as frequnecies reported to be "very high" | V12: 90
A13: "High" - includes frequencies reported in the literature as being between >50% and 80% as well as frequencies reported to be "high" | V13: 65
A14: "Moderate" - includes frequencies reported in the literature as being between >20% and 50% as well as frequencies reported to be "moderate" | V14: 35
A15: "Low" - includes frequencies reported in the literature as being between >10% and 20% as well as frequencies reported to be "low" | V15: 15
A16: "Very Low" - includes frequencies reported in the literature as being between >0% and 10% as well as frequencies reported to be "sporadic" and "very low" | V16: 5
A17: "Observed" - the literature reported that tumors were observed but the authors did not indicate frequency | V17: 2.5
A18: "Zero" - the literature reported that no tumors were observed | V18: 0
A20: For N=5, P-value is less than 0.05 for R2>=0.88
B22: Blood vessel | C22: Esophagus squamous cell carcinoma | D22: Forestomach | E22: Gallbladder adenoma | F22: Gastrointestinal tract tumor | H22: Intestine | I22: Liver | K22: Oral cavity squamous cell | L22: Pancreas | N22: Stomach | P22: Adrenal gland | Q22: Parathyroid gland carcinoma | R22: Pituitary gland | S22: Thyroid gland | T22: Ovary | U22: Placenta - Decidua deciduoma | V22: Uterus | W22: Vagina squamous cell papilloma | Y22: Mammary gland | AA22: Skin | AE22: Leukocyte | AF22: Lymphoid tissue lymphoma | AI22: Thymus thymoma | AJ22: Prostate gland adenoma | AK22: Seminal vesicle adenoma | AL22: Testis | AM22: CNS - Brain | AO22: PNS - Schwann cell | AQ22: Lung | AR22: Nose | AS22: Bone osteosarcoma | AT22: Adipose tissue lipoma | AU22: Connective tissue | AV22: Mesodermal cell | AW22: Mesothelium mesothelioma | AX22: Muscle | AZ22: Eye | BA22: Kidney | BC22: Urinary bladder papilloma
B23: 1.6428571 | C23: 1 | D23: 2.0833333 | E23: 1 | F23: 0 | H23: 1.625 | I23: 13.157895 | K23: 1 | L23: 1.6666667 | N23: 1 | P23: 4.4285714 | Q23: 1 | R23: 8.6 | S23: 2.5 | T23: 1.1533333 | U23: 1 | V23: 2 | W23: 1 | Y23: 1.4 | AA23: 0.915 | AE23: 2.93125 | AF23: 14 | AI23: 1.5 | AJ23: 0 | AK23: 1 | AL23: 1.1333333 | AM23: 0.625 | AO23: 1.03 | AQ23: 9.3 | AR23: 1 | AS23: 2 | AT23: 0.75 | AU23: 3.4375 | AV23: 1.2809524 | AW23: 0.275 | AX23: 0.86363636 | AZ23: 5.745 | BA23: 0.75 | BC23: 1

Sheet Sheet3
A1: Adipose tissue lipoma
A2: Adrenal gland
A3: Blood vessel
A4: Bone osteosarcoma
A5: Clitoral gland
A6: CNS - Brain
A7: Connective tissue
A8: Ear
A9: Esophagus squamous cell carcinoma
A10: Eye - Harderian gland
A11: Eye - Uvea - Melanocyte melanoma
A12: Forestomach
... A45: Vagina squamous cell papilloma

Sheet B6C3F1
A1: B6C3F1
A2: Tumor Name | B2: Organ(s) Affected | C2: Treatment Type | D2: Number of group records | E2: Frequency Range
A3: Adipose tissue lipoma | B3: Peritoneum - Mesentery | C3: None (spontaneous) | D3: 8 | E3: 1 | G3: Adipose tissue lipoma | H3: =AVERAGEIF(A$3:A$278,G3,E$3:E$278) -> 0.75
A4: Adipose tissue lipoma | B4: Skin | C4: None (spontaneous) | D4: 8 | E4: 1 | G4: Adrenal gland | H4: =AVERAGEIF(A$3:A$278,G4,E$3:E$278) -> 4.4285714
A5: Adipose tissue lipoma | B5: CNS - Brain | C5: None (spontaneous) | D5: 6 | E5: 1 | G5: Blood vessel | H5: =AVERAGEIF(A$3:A$278,G5,E$3:E$278) -> 1.6428571
A6: Adipose tissue lipoma | B6: Adipose tissue | C6: None (spontaneous) | D6: 2 | E6: 0 | G6: Bone osteosarcoma | H6: =AVERAGEIF(A$3:A$278,G6,E$3:E$278) -> 2
A7: Adrenal gland | B7: Adrenal gland - Capsule | C7: None (spontaneous) | D7: 10 | E7: 10 | G7: Clitoral gland | H7: =AVERAGEIF(A$3:A$278,G7,E$3:E$278) -> 0
A8: Adrenal gland | B8: Adrenal gland - Cortex | C8: None (spontaneous) | D8: 16 | E8: 12 | G8: CNS - Brain | H8: =AVERAGEIF(A$3:A$278,G8,E$3:E$278) -> 0.625
A9: Adrenal gland | B9: Adrenal gland - Cortex | C9: None (spontaneous) | D9: 10 | E9: 1 | G9: Connective tissue | H9: =AVERAGEIF(A$3:A$278,G9,E$3:E$278) -> 3.4375
A10: Adrenal gland | B10: Adrenal gland - Cortex | C10: None (spontaneous) | D10: 1 | E10: 1 | G10: Ear | H10: =AVERAGEIF(A$3:A$278,G10,E$3:E$278) -> 1
A11: Adrenal gland | B11: Adrenal gland - Cortex | C11: None (spontaneous) | D11: 1 | E11: 4 | G11: Esophagus squamous cell carcinoma | H11: =AVERAGEIF(A$3:A$278,G11,E$3:E$278) -> 1
A12: Adrenal gland | B12: Adrenal gland - Medulla | C12: None (spontaneous) | D12: 17 | E12: 3 | G12: Eye | H12: =AVERAGEIF(A$3:A$278,G12,E$3:E$278) -> 5.745
A13: Adrenal gland | B13: Adrenal gland - Medulla | C13: None (spontaneous) | D13: 2 | E13: 0 | G13: Forestomach | H13: =AVERAGEIF(A$3:A$278,G13,E$3:E$278) -> 2.0833333
A14: Blood vessel | B14: Blood vessel | C14: None (spontaneous) | D14: 50 | E14: 4 | G14: Gallbladder adenoma | H14: =AVERAGEIF(A$3:A$278,G14,E$3:E$278) -> 1
... A46: Blood vessel | B46: Muscle - Striated - Skeletal | C46: None (spontaneous) | D46: 10 | E46: 1 | G46: Vagina squamous cell papilloma | H46: =AVERAGEIF(A$3:A$278,G46,E$3:E$278) -> 1
A47: Blood vessel | B47: Preputial gland (male) | C47: None (spontaneous) | D47: 2 | E47: 0
A48: Blood vessel | B48: Testis | C48: None (spontaneous) | D48: 4 | E48: 1
A49: Blood vessel | B49: Lung | C49: None (spontaneous) | D49: 10 | E49: 1
A50: Blood vessel | B50: Kidney | C50: None (spontaneous) | D50: 6 | E50: 1
A51: Blood vessel | B51: Urinary bladder | C51: None (spontaneous) | D51: 8 | E51: 1
A52: Blood vessel | B52: Clitoral gland | C52: None (spontaneous) | D52: 6 | E52: 1
A53: Blood vessel | B53: Uterus | C53: None (spontaneous) | D53: 6 | E53: 2
A54: Blood vessel | B54: Ovary | C54: None (spontaneous) | D54: 4 | E54: 1
A55: Blood vessel | B55: Blood vessel | C55: None (spontaneous) | D55: 31 | E55: 10
A56: Bone osteosarcoma | B56: Bone | C56: None (spontaneous) | D56: 16 | E56: 2
A57: Clitoral gland | B57: Clitoral gland | C57: None (spontaneous) | D57: 1 | E57: 0
A58: Clitoral gland | B58: Clitoral gland | C58: None (spontaneous) | D58: 1 | E58: 0
... A278: Vagina squamous cell papilloma | B278: Vagina | C278: None (spontaneous) | D278: 4 | E278: 1

Sheet BALB cByJ
A1: Tumor Name | B1: Organ(s) Affected | C1: Treatment Type | D1: Number of | E1: Frequency Range
D2: Tumor Group Records | H2: Adipose tissue lipoma | I2: =AVERAGEIF($B$3:$B$260,H2,$E$3:$E$169) -> 0 | L2: http://tumor.informatics.jax.org/mtbwi/strainDetails.do?page=collapsed&key=311
A3: Adipose tissue lipoma | B3: Adipose tissue lipoma | C3: None (spontaneous) | D3: 2 | E3: 0 | H3: Adrenal gland | I3: =AVERAGEIF($B$3:$B$260,H3,$E$3:$E$169) -> 4.1666667
A4: Adipose tissue lipoma | B4: Adipose tissue lipoma | C4: None (spontaneous) | D4: 2 | E4: 0 | H4: Blood vessel | I4: =AVERAGEIF($B$3:$B$260,H4,$E$3:$E$169) -> 1.25
A5: Adrenal gland | B5: Adrenal gland | C5: None (spontaneous) | D5: 4 | E5: 0 | H5: Bone osteosarcoma | I5: =AVERAGEIF($B$3:$B$260,H5,$E$3:$E$169) -> #DIV/0!
A6: Adrenal gland | B6: Adrenal gland | C6: None (spontaneous) | D6: 1 | E6: 2.5 | H6: Clitoral gland | I6: =AVERAGEIF($B$3:$B$260,H6,$E$3:$E$169) -> 0
A7: Adrenal gland | B7: Adrenal gland | C7: None (spontaneous) | D7: 2 | E7: 0 | H7: CNS - Brain | I7: =AVERAGEIF($B$3:$B$260,H7,$E$3:$E$169) -> 0
A8: Adrenal gland | B8: Adrenal gland | C8: None (spontaneous) | D8: 2 | E8: 25 | H8: Connective tissue | I8: =AVERAGEIF($B$3:$B$260,H8,$E$3:$E$169) -> #DIV/0!
A9: Adrenal gland | B9: Adrenal gland | C9: None (spontaneous) | D9: 2 | E9: 0 | H9: Ear | I9: =AVERAGEIF($B$3:$B$260,H9,$E$3:$E$169) -> 0.625
A10: Adrenal gland | B10: Adrenal gland | C10: None (spontaneous) | D10: 7 | E10: 2.5 | H10: Esophagus squamous cell carcinoma | I10: =AVERAGEIF($B$3:$B$260,H10,$E$3:$E$169) -> #DIV/0!
A11: Adrenal gland | B11: Adrenal gland | C11: None (spontaneous) | D11: 2 | E11: 2.5 | H11: Eye | I11: =AVERAGEIF($B$3:$B$260,H11,$E$3:$E$169) -> 1.6666667
A12: Blood vessel | B12: Blood vessel | C12: None (spontaneous) | D12: 2 | E12: 0 | H12: Forestomach | I12: =AVERAGEIF($B$3:$B$260,H12,$E$3:$E$169) -> 0
A13: Blood vessel | B13: Blood vessel | C13: None (spontaneous) | D13: 1 | E13: 0 | H13: Gallbladder adenoma | I13: =AVERAGEIF($B$3:$B$260,H13,$E$3:$E$169) -> #DIV/0!
A14: Blood vessel | B14: Blood vessel | C14: None (spontaneous) | D14: 1 | E14: 2.5 | H14: Gastrointestinal tract tumor | I14: =AVERAGEIF($B$3:$B$260,H14,$E$3:$E$169) -> #DIV/0!
... A45: Intestine - Large Intestine - Colon lesion | B45: Intestine | C45: None (spontaneous) | D45: 1 | E45: 0 | H45: Vagina squamous cell papilloma | I45: =AVERAGEIF($B$3:$B$260,H45,$E$3:$E$169) -> #DIV/0!
A46: Intestine - Small Intestine - Brunner's gland adenoma | B46: Intestine | C46: None (spontaneous) | D46: 2 | E46: 0
A47: Intestine - Small Intestine - Brunner's gland hyperplasia | B47: Intestine | C47: None (spontaneous) | D47: 2 | E47: 0
A48: Intestine - Small Intestine - Duodenum adenoma | B48: Intestine | C48: None (spontaneous) | D48: 2 | E48: 0
A49: Intestine - Small Intestine - Duodenum cyst | B49: Intestine | C49: None (spontaneous) | D49: 2 | E49: 0
A50: Intestine - Small Intestine - Duodenum hyperplasia | B50: Intestine | C50: None (spontaneous) | D50: 2 | E50: 0
A51: Intestine - Small Intestine - Duodenum polyp | B51: Intestine | C51: None (spontaneous) | D51: 6 | E51: 1.25
A52: Intestine - Small Intestine - Ileum polyp | B52: Intestine | C52: None (spontaneous) | D52: 3 | E52: 2.5
A53: Intestine - Small Intestine - Jejunum hyperplasia | B53: Intestine | C53: None (spontaneous) | D53: 2 | E53: 0
A54: Intestine - Small Intestine - Jejunum polyp | B54: Intestine | C54: None (spontaneous) | D54: 2 | E54: 0
A55: Intestine lesion | B55: Intestine | C55: None (spontaneous) | D55: 1 | E55: 0
A56: Kidney adenoma | B56: Kidney | C56: None (spontaneous) | D56: 2 | E56: 0
A57: Leukocyte - Lymphocyte - B-lymphocyte - Plasma cell neoplasm | B57: Spleen | C57: None (spontaneous) | D57: 1 | E57: 2.5
... A168: (Unspecified organ) tumor | B168: (Unspecified organ) | C168: None (spontaneous) | D168: 2 | E168: 2.5

Sheet CBA
A1: Tumor Name | B1: Organ(s) Affected | C1: Treatment Type | D1: Number of | E1: Frequency Range | L1: http://tumor.informatics.jax.org/mtbwi/strainDetails.do?page=collapsed&key=212
A2: Adrenal gland - Cortex adenoma | B2: Adrenal gland | C2: None (spontaneous) | D2: 1 | E2: 0 | H2: Adipose tissue lipoma | I2: =AVERAGEIF($B$2:$B$167,H2,$E$2:$E$167) -> #DIV/0!
A3: Adrenal gland - Cortex lesion | B3: Adrenal gland | C3: None (spontaneous) | D3: 1 | E3: 16 | H3: Adrenal gland | I3: =AVERAGEIF($B$2:$B$167,H3,$E$2:$E$167) -> 13.833333 | L3: http://tumor.informatics.jax.org/mtbwi/strainDetails.do?page=collapsed&key=9066
A4: Adrenal gland - Medulla hyperplasia | B4: Adrenal gland | C4: None (spontaneous) | D4: 1 | E4: 2 | H4: Blood vessel | I4: =AVERAGEIF($B$2:$B$167,H4,$E$2:$E$167) -> 0
A5: Adrenal gland - Medulla pheochromocytoma | B5: Adrenal gland | C5: None (spontaneous) | D5: 1 | E5: 2 | H5: Bone osteosarcoma | I5: =AVERAGEIF($B$2:$B$167,H5,$E$2:$E$167) -> #DIV/0!
A6: Adrenal gland - Medulla pheochromocytoma - benign | B6: Adrenal gland | C6: None (spontaneous) | D6: 1 | E6: 2 | H6: Clitoral gland | I6: =AVERAGEIF($B$2:$B$167,H6,$E$2:$E$167) -> #DIV/0!
A7: Adrenal gland - Medulla pheochromocytoma - malignant | B7: Adrenal gland | C7: None (spontaneous) | D7: 1 | E7: 0 | H7: CNS - Brain | I7: =AVERAGEIF($B$2:$B$167,H7,$E$2:$E$167) -> #DIV/0!
A8: Adrenal gland - Subcapsular cell adenoma | B8: Adrenal gland | C8: None (spontaneous) | D8: 1 | E8: 0 | H8: Connective tissue | I8: =AVERAGEIF($B$2:$B$167,H8,$E$2:$E$167) -> #DIV/0!
A9: Adrenal gland - Subcapsular cell hyperplasia | B9: Adrenal gland | C9: None (spontaneous) | D9: 1 | E9: 100 | H9: Ear | I9: =AVERAGEIF($B$2:$B$167,H9,$E$2:$E$167) -> #DIV/0!
A10: Blood vessel hemangioma | B10: Blood vessel | C10: None (spontaneous) | D10: 1 | E10: 0 | H10: Esophagus squamous cell carcinoma | I10: =AVERAGEIF($B$2:$B$167,H10,$E$2:$E$167) -> #DIV/0!
A11: Blood vessel hemangiosarcoma | B11: Blood vessel | C11: None (spontaneous) | D11: 1 | E11: 0 | H11: Eye | I11: =AVERAGEIF($B$2:$B$167,H11,$E$2:$E$167) -> 12.5
A12: Eye - Harderian gland adenoma | B12: Eye | C12: None (spontaneous) | D12: 1 | E12: 20 | H12: Forestomach | I12: =AVERAGEIF($B$2:$B$167,H12,$E$2:$E$167) -> 2
A13: Eye - Harderian gland carcinoma | B13: Eye | C13: None (spontaneous) | D13: 1 | E13: 0 | H13: Gallbladder adenoma | I13: =AVERAGEIF($B$2:$B$167,H13,$E$2:$E$167) -> #DIV/0!
A14: Eye - Harderian gland hyperplasia | B14: Eye | C14: None (spontaneous) | D14: 1 | E14: 10 | H14: Gastrointestinal tract tumor | I14: =AVERAGEIF($B$2:$B$167,H14,$E$2:$E$167) -> #DIV/0!
A15: Eye - Harderian gland tumor | B15: Eye | C15: None (spontaneous) | D15: 1 | E15: 20 | H15: Heart hyperplasia - endothelial | I15: =AVERAGEIF($B$2:$B$167,H15,$E$2:$E$167) -> #DIV/0!
... A45: Pancreas - Islet of Langerhans hyperplasia | B45: Pancreas | C45: None (spontaneous) | D45: 1 | E45: 35 | H45: Vagina squamous cell papilloma | I45: =AVERAGEIF($B$2:$B$167,H45,$E$2:$E$167) -> #DIV/0!
A46: Pituitary gland - Pars distalis adenocarcinoma | B46: Pituitary gland | C46: None (spontaneous) | D46: 1 | E46: 0
A47: Pituitary gland - Pars distalis adenoma | B47: Pituitary gland | C47: None (spontaneous) | D47: 1 | E47: 0
A48: Pituitary gland - Pars distalis hyperplasia | B48: Pituitary gland | C48: None (spontaneous) | D48: 1 | E48: 0
A49: Pituitary gland - Pars distalis tumor | B49: Pituitary gland | C49: None (spontaneous) | D49: 1 | E49: 0
A50: Skin - Melanocyte melanoma - malignant | B50: Skin | C50: None (spontaneous) | D50: 1 | E50: 0
A51: Thyroid gland - Follicular cell adenoma | B51: Thyroid gland | C51: None (spontaneous) | D51: 1 | E51: 0
A52: Thyroid gland - Follicular cell hyperplasia | B52: Thyroid gland | C52: None (spontaneous) | D52: 1 | E52: 50
A53: Thyroid gland - Medulla - C cell adenoma | B53: Thyroid gland | C53: None (spontaneous) | D53: 1 | E53: 0
A54: Uterus - Endometrium - Stroma polyp | B54: Uterus | C54: None (spontaneous) | D54: 1 | E54: 0
A55: Uterus - Endometrium adenocarcinoma | B55: Uterus | C55: None (spontaneous) | D55: 1 | E55: 0
A56: Uterus - Endometrium adenoma | B56: Uterus | C56: None (spontaneous) | D56: 1 | E56: 0
A57: Uterus - Endometrium hyperplasia - cystic | B57: Uterus | C57: None (spontaneous) | D57: 1 | E57: 72
... A86: Mammary gland tumor | B86: Mammary gland | C86: None (spontaneous) | D86: 1 | E86: 2.5

Sheet C3H
A1: Tumor Name | B1: Organ(s) Affected | C1: Treatment Type | D1: Number of | E1: Frequency Range | L1: http://tumor.informatics.jax.org/mtbwi/strainDetails.do?page=collapsed&key=47
A2: Adrenal gland - Cortex tumor | B2: Adrenal gland | C2: None (spontaneous) | D2: 1 | E2: 2.5 | H2: Adipose tissue lipoma | I2: =AVERAGEIF($B$2:$B$68,H2,$E$2:$E$68) -> #DIV/0!
A3: Bone osteosarcoma | B3: Bone | C3: None (spontaneous) | D3: 1 | E3: 2.5 | H3: Adrenal gland | I3: =AVERAGEIF($B$2:$B$68,H3,$E$2:$E$68) -> 51.25 | L3: http://tumor.informatics.jax.org/mtbwi/strainDetails.do?page=collapsed&key=161
A4: Eye - Harderian gland tumor | B4: Eye | C4: None (spontaneous) | D4: 2 | E4: 2.5 | H4: Blood vessel | I4: =AVERAGEIF($B$2:$B$68,H4,$E$2:$E$68) -> 0.9
A5: Leukocyte - Lymphocyte - B-lymphocyte - Plasma cell tumor | B5: Leukocyte | C5: None (spontaneous) | D5: 1 | E5: 2.5 | H5: Bone osteosarcoma | I5: =AVERAGEIF($B$2:$B$68,H5,$E$2:$E$68) -> #DIV/0! | L5: http://tumor.informatics.jax.org/mtbwi/strainDetails.do?page=collapsed&key=9071
A6: Leukocyte - Lymphocyte leukemia - lymphocytic | B6: Leukocyte | C6: None (spontaneous) | D6: 1 | E6: 0 | H6: Clitoral gland | I6: =AVERAGEIF($B$2:$B$68,H6,$E$2:$E$68) -> #DIV/0!
A7: Leukocyte - Lymphocyte lymphoma - small lymphocytic | B7: Leukocyte | C7: None (spontaneous) | D7: 1 | E7: 2.5 | H7: CNS - Brain | I7: =AVERAGEIF($B$2:$B$68,H7,$E$2:$E$68) -> #DIV/0! | L7: http://tumor.informatics.jax.org/mtbwi/strainDetails.do?page=collapsed&key=827
A8: Leukocyte leukemia | B8: Leukocyte | C8: None (spontaneous) | D8: 2 | E8: 0 | H8: Connective tissue | I8: =AVERAGEIF($B$2:$B$68,H8,$E$2:$E$68) -> #DIV/0!
A9: Leukocyte lymphoma | B9: Leukocyte | C9: None (spontaneous) | D9: 1 | E9: 17 | H9: Ear | I9: =AVERAGEIF($B$2:$B$68,H9,$E$2:$E$68) -> #DIV/0!
A10: Liver hepatocellular carcinoma | B10: Liver | C10: None (spontaneous) | D10: 1 | E10: 0 | H10: Esophagus squamous cell carcinoma | I10: =AVERAGEIF($B$2:$B$68,H10,$E$2:$E$68) -> #DIV/0!
A11: Liver hepatoma | B11: Liver | C11: None (spontaneous) | D11: 13 | E11: 45 | H11: Eye | I11: =AVERAGEIF($B$2:$B$68,H11,$E$2:$E$68) -> 1.75
A12: Liver tumor | B12: Liver | C12: None (spontaneous) | D12: 4 | E12: 55 | H12: Forestomach | I12: =AVERAGEIF($B$2:$B$68,H12,$E$2:$E$68) -> #DIV/0!
A13: Lung adenoma | B13: Lung | C13: None (spontaneous) | D13: 2 | E13: 0 | H13: Gallbladder adenoma | I13: =AVERAGEIF($B$2:$B$68,H13,$E$2:$E$68) -> #DIV/0!
A14: Lung tumor | B14: Lung | C14: None (spontaneous) | D14: 3 | E14: 8 | H14: Gastrointestinal tract tumor | I14: =AVERAGEIF($B$2:$B$68,H14,$E$2:$E$68) -> #DIV/0!
A15: Mammary gland adenocarcinoma | B15: Mammary gland | C15: None (spontaneous) | D15: 2 | E15: 65 | H15: Heart hyperplasia - endothelial | I15: =AVERAGEIF($B$2:$B$68,H15,$E$2:$E$68) -> #DIV/0!
A16: Mammary gland tumor | B16: Mammary gland | C16: None (spontaneous) | D16: 9 | E16: 35 | H16: Intestine | I16: =AVERAGEIF($B$2:$B$68,H16,$E$2:$E$68) -> #DIV/0!
A17: Mesodermal cell/mesoblast sarcoma | B17: Mesodermal cell | C17: None (spontaneous) | D17: 2 | E17: 1.25 | H17: Kidney | I17: =AVERAGEIF($B$2:$B$68,H17,$E$2:$E$68) -> #DIV/0!
A18: Ovary - Germ cell teratoma | B18: Ovary | C18: None (spontaneous) | D18: 1 | E18: 2.5 | H18: Leukocyte | I18: =AVERAGEIF($B$2:$B$68,H18,$E$2:$E$68) -> 2.846
A19: Ovary cyst | B19: Ovary | C19: None (spontaneous) | D19: 1 | E19: 19 | H19: Liver | I19: =AVERAGEIF($B$2:$B$68,H19,$E$2:$E$68) -> 24.4125
... A22: (Unspecified organ) tumor - benign | B22: (Unspecified organ) | C22: None (spontaneous) | D22: 1 | E22: 0 | H22: Mammary gland | I22: =AVERAGEIF($B$2:$B$68,H22,$E$2:$E$68) -> 67.1
H23: Mesodermal cell | I23: =AVERAGEIF($B$2:$B$68,H23,$E$2:$E$68) -> 1.25
A24: Adrenal gland - Subcapsular cell hyperplasia | B24: Adrenal gland | C24: None (spontaneous) | D24: 2 | E24: 100 | H24: Mesothelium mesothelioma | I24: =AVERAGEIF($B$2:$B$68,H24,$E$2:$E$68) -> #DIV/0!
A25: Blood vessel hemangioendothelioma | B25: Blood vessel | C25: None (spontaneous) | D25: 1 | E25: 0.9 | H25: Muscle | I25: =AVERAGEIF($B$2:$B$68,H25,$E$2:$E$68) -> #DIV/0!
A26: Eye - Harderian gland tumor | B26: Eye | C26: None (spontaneous) | D26: 1 | E26: 1 | H26: Nose | I26: =AVERAGEIF($B$2:$B$68,H26,$E$2:$E$68) -> #DIV/0!
A27: Liver - Hepatocyte foci - basophilic | B27: Liver | C27: None (spontaneous) | D27: 1 | E27: 2.5 | H27: Oral cavity squamous cell | I27: =AVERAGEIF($B$2:$B$68,H27,$E$2:$E$68) -> #DIV/0!
A28: Liver hepatocellular adenoma | B28: Liver | C28: None (spontaneous) | D28: 1 | E28: 2.5 | H28: Ovary | I28: =AVERAGEIF($B$2:$B$68,H28,$E$2:$E$68) -> 10.75
A29: Liver hepatocellular carcinoma | B29: Liver | C29: None (spontaneous) | D29: 1 | E29: 2.5 | H29: Pancreas | I29: =AVERAGEIF($B$2:$B$68,H29,$E$2:$E$68) -> #DIV/0!
A30: Liver hepatoma | B30: Liver | C30: None (spontaneous) | D30: 6 | E30: 85.3 | H30: Parathyroid gland carcinoma | I30: =AVERAGEIF($B$2:$B$68,H30,$E$2:$E$68) -> #DIV/0!
A31: Liver tumor - basophilic | B31: Liver | C31: None (spontaneous) | D31: 1 | E31: 2.5 | H31: Pituitary gland | I31: =AVERAGEIF($B$2:$B$68,H31,$E$2:$E$68) -> #DIV/0!
A32: Lung tumor | B32: Lung | C32: None (spontaneous) | D32: 2 | E32: 4.5 | H32: Placenta - Decidua deciduoma | I32: =AVERAGEIF($B$2:$B$68,H32,$E$2:$E$68) -> #DIV/0!
A33: Mammary gland adenocarcinoma | B33: Mammary gland | C33: None (spontaneous) | D33: 2 | E33: 88 | H33: PNS - Schwann cell | I33: =AVERAGEIF($B$2:$B$68,H33,$E$2:$E$68) -> 2.5
A34: Mammary gland tumor | B34: Mammary gland | C34: None (spontaneous) | D34: 11 | E34: 82.5 | H34: Preputial gland (male) | I34: =AVERAGEIF($B$2:$B$68,H34,$E$2:$E$68) -> #DIV/0!
A35: Urinary bladder carcinoma | B35: Urinary bladder | C35: None (spontaneous) | D35: 1 | E35: 0 | H35: Prostate gland adenoma | I35: =AVERAGEIF($B$2:$B$68,H35,$E$2:$E$68) -> #DIV/0!
A36: (Unspecified organ) reticulum cell neoplasm | B36: (Unspecified organ) | C36: None (spontaneous) | D36: 1 | E36: 1 | H36: Seminal vesicle adenoma | I36: =AVERAGEIF($B$2:$B$68,H36,$E$2:$E$68) -> #DIV/0!
H37: Skin | I37: =AVERAGEIF($B$2:$B$68,H37,$E$2:$E$68) -> #DIV/0!
A38: Erythrocyte hyperplasia | B38: Spleen | C38: None (spontaneous) | D38: 4 | E38: 7 | H38: Stomach - Glandular | I38: =AVERAGEIF($B$2:$B$68,H38,$E$2:$E$68) -> #DIV/0!
A39: Leukocyte - Lymphocyte - B-lymphocyte - Plasma cell neoplasm | B39: Leukocyte | C39: None (spontaneous) | D39: 1 | E39: 0 | H39: Testis | I39: =AVERAGEIF($B$2:$B$68,H39,$E$2:$E$68) -> #DIV/0!
A40: Leukocyte - Lymphocyte hyperplasia | B40: Lymph node | C40: None (spontaneous) | D40: 4 | E40: 0.61 | H40: Thymus thymoma | I40: =AVERAGEIF($B$2:$B$68,H40,$E$2:$E$68) -> #DIV/0!
A41: Leukocyte - Lymphocyte hyperplasia | B41: Spleen | C41: None (spontaneous) | D41: 4 | E41: 10 | H41: Thyroid gland | I41: =AVERAGEIF($B$2:$B$68,H41,$E$2:$E$68) -> #DIV/0!
A42: Leukocyte - Lymphocyte lymphoma - lymphoblastic | B42: Leukocyte | C42: None (spontaneous) | D42: 4 | E42: 1.8 | H42: Tooth odontoma | I42: =AVERAGEIF($B$2:$B$68,H42,$E$2:$E$68) -> #DIV/0!
...

Sheet C57BL6J
A1: Adipose tissue - White lipoma | B1: Adipose tissue | C1: None (spontaneous) | D1: 2 | E1: 0 | L1: http://www.tumor.informatics.jax.org/mtbwi/strainDetails.do?page=collapsed&key=143
A2: Adipose tissue lipoma | B2: Adipose tissue | C2: None (spontaneous) | D2: 1 | E2: 2.5 | H2: Adipose tissue lipoma | I2: =AVERAGEIF($B$1:$B$370,H2,$E$1:$E$286) -> #DIV/0!
A3: Adipose tissue lipoma | B3: Adipose tissue | C3: None (spontaneous) | D3: 2 | E3: 0 | H3: Adrenal gland | I3: =AVERAGEIF($B$1:$B$370,H3,$E$1:$E$286) -> 3.09375
A4: Adipose tissue lipoma - pedunculated | B4: Adipose tissue | C4: None (spontaneous) | D4: 2 | E4: 2.5 | H4: Blood vessel | I4: =AVERAGEIF($B$1:$B$370,H4,$E$1:$E$286) -> 1.75
A5: Adrenal gland - Cortex adenoma | B5: Adrenal gland | C5: None (spontaneous) | D5: 3 | E5: 1.25 | H5: Bone osteosarcoma | I5: =AVERAGEIF($B$1:$B$370,H5,$E$1:$E$286) -> #DIV/0!
A6: Adrenal gland - Medulla pheochromocytoma | B6: Adrenal gland | C6: None (spontaneous) | D6: 2 | E6: 0 | H6: Clitoral gland | I6: =AVERAGEIF($B$1:$B$370,H6,$E$1:$E$286) -> #DIV/0!
A7: Adrenal gland - Medulla pheochromocytoma - malignant | B7: Adrenal gland | C7: None (spontaneous) | D7: 1 | E7: 1 | H7: CNS - Brain | I7: =AVERAGEIF($B$1:$B$370,H7,$E$1:$E$286) -> 0
A8: Adrenal gland - Subcapsular cell hyperplasia | B8: Adrenal gland | C8: None (spontaneous) | D8: 1 | E8: 2.5 | H8: Connective tissue | I8: =AVERAGEIF($B$1:$B$370,H8,$E$1:$E$286) -> 1.75
A9: Adrenal gland - Subcapsular cell hyperplasia - spindle cell | B9: Adrenal gland | C9: None (spontaneous) | D9: 2 | E9: 17.5 | H9: Ear | I9: =AVERAGEIF($B$1:$B$370,H9,$E$1:$E$286) -> 0
A10: Adrenal gland hyperplasia - nodular | B10: Adrenal gland | C10: None (spontaneous) | D10: 2 | E10: 0 | H10: Esophagus squamous cell carcinoma | I10: =AVERAGEIF($B$1:$B$370,H10,$E$1:$E$286) -> #DIV/0!
A11: Adrenal gland hyperplasia - spindle cell | B11: Adrenal gland | C11: None (spontaneous) | D11: 4 | E11: 2.5 | H11: Eye | I11: =AVERAGEIF($B$1:$B$370,H11,$E$1:$E$286) -> 1.25
A12: Adrenal gland tumor - carcinoid | B12: Adrenal gland | C12: None (spontaneous) | D12: 2 | E12: 0 | H12: Forestomach | I12: =AVERAGEIF($B$1:$B$370,H12,$E$1:$E$286) -> 1.6666667
A13: Blood vessel - Aorta metaplasia - cartilaginous | B13: Blood vessel | C13: None (spontaneous) | D13: 1 | E13: 0 | H13: Gallbladder adenoma | I13: =AVERAGEIF($B$1:$B$370,H13,$E$1:$E$286) -> #DIV/0!
... A45: Epididymis cyst | B45: Epididymis | C45: None (spontaneous) | D45: 1 | E45: 0 | H45: Vagina squamous cell papilloma | I45: =AVERAGEIF($B$1:$B$370,H45,$E$1:$E$286) -> #DIV/0!
A46: Erythrocyte leukemia - erythroleukemia | B46: Spleen | C46: None (spontaneous) | D46: 3 | E46: 0
A47: Erythrocyte leukemia - erythroleukemia | B47: Liver | C47: None (spontaneous) | D47: 1 | E47: 0
A48: Erythrocyte neoplasm | B48: Erythrocyte | C48: None (spontaneous) | D48: 2 | E48: 0
A49: Esophagus hyperplasia | B49: Esophagus | C49: None (spontaneous) | D49: 3 | E49: 0
A50: Esophagus tumor | B50: Esophagus | C50: None (spontaneous) | D50: 1 | E50: 0
A51: Eye - Harderian gland adenoma | B51: Eye | C51: None (spontaneous) | D51: 1 | E51: 2.5
A52: Eye - Harderian gland neoplasm | B52: Eye | C52: None (spontaneous) | D52: 4 | E52: 0
A53: Forestomach hyperplasia | B53: Forestomach | C53: None (spontaneous) | D53: 1 | E53: 0
A54: Forestomach hyperplasia - papillary | B54: Forestomach | C54: None (spontaneous) | D54: 2 | E54: 0
A55: Forestomach papilloma | B55: Forestomach | C55: None (spontaneous) | D55: 2 | E55: 5
A56: Gallbladder cyst | B56: Gallbladder | C56: None (spontaneous) | D56: 2 | E56: 0
A57: Gallbladder hyperplasia | B57: Gallbladder | C57: None (spontaneous) | D57: 2 | E57: 0
... A266: (Unspecified organ) tumor | B266: (Unspecified organ) | C266: None (spontaneous) | D266: 7 | E266: 7.5

Sheet Summary
J1: Pearson
B2: B6C3F1 | C2: BalbC/Jy | D2: CBA | E2: C3H | F2: C57BL/6 | G2: CC002 | H2: CC011 | I2: CC013 | J2: Ar_tau | K2: Ar_Rho | L2: Fe_tau | M2: Fe_Rho | N2: X0.1Gy_tau | O2: X1Gy_tau | P2: X1Gy_RIF_inter | Q2: X4Gy_tau | R2: X4Gy_RIF_inter | T2: Ar_tau | U2: Ar_Rho | V2: Fe_tau | W2: Fe_Rho | X2: X0.1Gy_tau | Y2: X1Gy_tau | Z2: X1Gy_RIF_inter | AA2: X4Gy_tau | AB2: X4Gy_RIF_inter
A3: Adipose tissue lipoma | B3: =B6C3F1!H3 -> 0.75 | C3: ='BALB cByJ'!I2 -> 0 | D3: =CBA!I2 -> #DIV/0! | E3: ='C3H'!I2 -> #DIV/0! | F3: ='C57BL6J'!I2 -> #DIV/0! | G3: 0 | H3: 0 | I3: 0 | S3: B6C3 | T3: 5.3846309 | U3: 0.88706908 | V3: 6.1092604 | W3: 0.85723768 | X3: 4.245442 | Y3: 9.0566585 | Z3: 3.614172 | AA3: 20.261998 | AB3: 9.0566585
A4: Adrenal gland | B4: =B6C3F1!H4 -> 4.4285714 | C4: ='BALB cByJ'!I3 -> 4.1666667 | D4: =CBA!I3 -> 13.833333 | E4: ='C3H'!I3 -> 51.25 | F4: ='C57BL6J'!I3 -> 3.09375 | G4: 0 | H4: 0 | I4: 0 | J4: =PEARSON($B4:$F4,T$3:T$7) -> 0.035842296 | K4: =PEARSON($B4:$F4,U$3:U$7) -> -0.48359637 | L4: =PEARSON($B4:$F4,V$3:V$7) -> 0.75729549 | M4: =PEARSON($B4:$F4,W$3:W$7) -> -0.10370715 | N4: =PEARSON($B4:$F4,X$3:X$7) -> -0.16949779 | O4: =PEARSON($B4:$F4,Y$3:Y$7) -> 0.90032187 | P4: =PEARSON($B4:$F4,Z$3:Z$7) -> 0.51044943 | Q4: =PEARSON($B4:$F4,AA$3:AA$7) -> 0.7319894 | R4: =PEARSON($B4:$F4,AB$3:AB$7) -> 0.90032187 | S4: BALBC | T4: 7.2797006 | U4: 0.90177099 | V4: 6.9942104 | W4: 0.90753742 | X4: 2.3854505 | Y4: 10.195735 | Z4: 3.8112864 | AA4: 26.947275 | AB4: 10.195735
A5: Blood vessel | B5: =B6C3F1!H5 -> 1.6428571 | C5: ='BALB cByJ'!I4 -> 1.25 | D5: =CBA!I4 -> 0 | E5: ='C3H'!I4 -> 0.9 | F5: ='C57BL6J'!I4 -> 1.75 | G5: 0 | H5: 0 | I5: 0 | J5: =PEARSON($B5:$F5,T$3:T$7) -> -0.39003211 | K5: =PEARSON($B5:$F5,U$3:U$7) -> 0.12385538 | L5: =PEARSON($B5:$F5,V$3:V$7) -> -0.79066227 | M5: =PEARSON($B5:$F5,W$3:W$7) -> -0.026784578 | N5: =PEARSON($B5:$F5,X$3:X$7) -> 0.11611563 | O5: =PEARSON($B5:$F5,Y$3:Y$7) -> -0.50175976 | P5: =PEARSON($B5:$F5,Z$3:Z$7) -> 0.52131797 | Q5: =PEARSON($B5:$F5,AA$3:AA$7) -> -0.19069219 | R5: =PEARSON($B5:$F5,AB$3:AB$7) -> -0.50175976 | S5: CBA | T5: 6.2424646 | U5: 0.88424278 | V5: 7.5134753 | W5: 0.86876757 | X5: 3.1569833 | Y5: 10.072893 | Z5: 2.8177823 | AA5: 22.421855 | AB5: 10.072893
A6: Bone osteosarcoma | B6: =B6C3F1!H6 -> 2 | C6: ='BALB cByJ'!I5 -> #DIV/0! | D6: =CBA!I5 -> #DIV/0! | E6: ='C3H'!I5 -> #DIV/0! | F6: ='C57BL6J'!I5 -> #DIV/0! | G6: 0 | H6: 0 | I6: 0 | J6: =PEARSON($B6:$F6,T$3:T$7) -> #DIV/0! | K6: =PEARSON($B6:$F6,U$3:U$7) -> #DIV/0! | L6: =PEARSON($B6:$F6,V$3:V$7) -> #DIV/0! | M6: =PEARSON($B6:$F6,W$3:W$7) -> #DIV/0! | N6: =PEARSON($B6:$F6,X$3:X$7) -> #DIV/0! | O6: =PEARSON($B6:$F6,Y$3:Y$7) -> #DIV/0! | P6: =PEARSON($B6:$F6,Z$3:Z$7) -> #DIV/0! | Q6: =PEARSON($B6:$F6,AA$3:AA$7) -> #DIV/0! | R6: =PEARSON($B6:$F6,AB$3:AB$7) -> #DIV/0! | S6: C3H | T6: 6.0445828 | U6: 0.87988505 | V6: 7.7699679 | W6: 0.87286614 | X6: 2.8029287 | Y6: 11.665031 | Z6: 4.2201535 | AA6: 29.518451 | AB6: 11.665031
A7: Clitoral gland | B7: =B6C3F1!H7 -> 0 | C7: ='BALB cByJ'!I6 -> 0 | D7: =CBA!I6 -> #DIV/0! | E7: ='C3H'!I6 -> #DIV/0! | F7: ='C57BL6J'!I6 -> #DIV/0! | G7: 0 | H7: 0 | I7: 0 | J7: =PEARSON($B7:$F7,T$3:T$7) -> #DIV/0! | K7: =PEARSON($B7:$F7,U$3:U$7) -> #DIV/0! | L7: =PEARSON($B7:$F7,V$3:V$7) -> #DIV/0! | M7: =PEARSON($B7:$F7,W$3:W$7) -> #DIV/0! | N7: =PEARSON($B7:$F7,X$3:X$7) -> #DIV/0! | O7: =PEARSON($B7:$F7,Y$3:Y$7) -> #DIV/0! | P7: =PEARSON($B7:$F7,Z$3:Z$7) -> #DIV/0! | Q7: =PEARSON($B7:$F7,AA$3:AA$7) -> #DIV/0! | R7: =PEARSON($B7:$F7,AB$3:AB$7) -> #DIV/0! | S7: C57 | T7: 5.2886282 | U7: 0.88138529 | V7: 6.4638732 | W7: 0.86890959 | X7: 2.6739665 | Y7: 9.0333446 | Z7: 3.5618668 | AA7: 22.339624 | AB7: 9.0333446
A8: CNS - Brain | B8: =B6C3F1!H8 -> 0.625 | C8: ='BALB cByJ'!I7 -> 0 | D8: =CBA!I7 -> #DIV/0! | E8: ='C3H'!I7 -> #DIV/0! | F8: ='C57BL6J'!I7 -> 0 | G8: 0 | H8: 0 | I8: 0 | J8: =PEARSON($B8:$F8,T$3:T$7) -> #DIV/0! | K8: =PEARSON($B8:$F8,U$3:U$7) -> #DIV/0! | L8: =PEARSON($B8:$F8,V$3:V$7) -> #DIV/0! | M8: =PEARSON($B8:$F8,W$3:W$7) -> #DIV/0! | N8: =PEARSON($B8:$F8,X$3:X$7) -> #DIV/0! | O8: =PEARSON($B8:$F8,Y$3:Y$7) -> #DIV/0! | P8: =PEARSON($B8:$F8,Z$3:Z$7) -> #DIV/0! | Q8: =PEARSON($B8:$F8,AA$3:AA$7) -> #DIV/0! | R8: =PEARSON($B8:$F8,AB$3:AB$7) -> #DIV/0! | S8: CC002 | T8: 5.5249999 | U8: 0.87371599 | V8: 6.1430721 | W8: 0.87657367 | X8: 2.8824021 | Y8: 10.201013 | Z8: 3.2334042 | AA8: 34.808324 | AB8: 10.201013
A9: Connective tissue | B9: =B6C3F1!H9 -> 3.4375 | C9: ='BALB cByJ'!I8 -> #DIV/0! | D9: =CBA!I8 -> #DIV/0! | E9: ='C3H'!I8 -> #DIV/0! | F9: ='C57BL6J'!I8 -> 1.75 | G9: 0 | H9: 0 | I9: 0 | J9: =PEARSON($B9:$F9,T$3:T$7) -> #DIV/0! | K9: =PEARSON($B9:$F9,U$3:U$7) -> #DIV/0! | L9: =PEARSON($B9:$F9,V$3:V$7) -> #DIV/0! | M9: =PEARSON($B9:$F9,W$3:W$7) -> #DIV/0! | N9: =PEARSON($B9:$F9,X$3:X$7) -> #DIV/0! | O9: =PEARSON($B9:$F9,Y$3:Y$7) -> #DIV/0! | P9: =PEARSON($B9:$F9,Z$3:Z$7) -> #DIV/0! | Q9: =PEARSON($B9:$F9,AA$3:AA$7) -> #DIV/0! | R9: =PEARSON($B9:$F9,AB$3:AB$7) -> #DIV/0! | S9: CC011 | T9: 6.297692 | U9: 0.89448361 | V9: 6.6107178 | W9: 0.91326127 | X9: 2.7994094 | Y9: 9.5533814 | Z9: 4.3946552 | AA9: 22.518948 | AB9: 9.5533814
A10: Ear | B10: =B6C3F1!H10 -> 1 | C10: ='BALB cByJ'!I9 -> 0.625 | D10: =CBA!I9 -> #DIV/0! | E10: ='C3H'!I9 -> #DIV/0! | F10: ='C57BL6J'!I9 -> 0 | G10: 0 | H10: 0 | I10: 0 | J10: =PEARSON($B10:$F10,T$3:T$7) -> #DIV/0! | K10: =PEARSON($B10:$F10,U$3:U$7) -> #DIV/0! | L10: =PEARSON($B10:$F10,V$3:V$7) -> #DIV/0! | M10: =PEARSON($B10:$F10,W$3:W$7) -> #DIV/0! | N10: =PEARSON($B10:$F10,X$3:X$7) -> #DIV/0! | O10: =PEARSON($B10:$F10,Y$3:Y$7) -> #DIV/0! | P10: =PEARSON($B10:$F10,Z$3:Z$7) -> #DIV/0! | Q10: =PEARSON($B10:$F10,AA$3:AA$7) -> #DIV/0! | R10: =PEARSON($B10:$F10,AB$3:AB$7) -> #DIV/0! | S10: CC013 | T10: 4.0569214 | U10: 0.80669125 | V10: 4.9886443 | W10: 0.88061206 | X10: 2.08717 | Y10: 10.572801 | Z10: 5.681599 | AA10: 25.23366 | AB10: 10.572801
A11: Esophagus squamous cell carcinoma | B11: =B6C3F1!H11 -> 1 | C11: ='BALB cByJ'!I10 -> #DIV/0! | D11: =CBA!I10 -> #DIV/0! | E11: ='C3H'!I10 -> #DIV/0! | F11: ='C57BL6J'!I10 -> #DIV/0! | G11: 0 | H11: 0 | J11: =PEARSON($B11:$F11,T$3:T$7) -> #DIV/0! | K11: =PEARSON($B11:$F11,U$3:U$7) -> #DIV/0! | L11: =PEARSON($B11:$F11,V$3:V$7) -> #DIV/0! | M11: =PEARSON($B11:$F11,W$3:W$7) -> #DIV/0! | N11: =PEARSON($B11:$F11,X$3:X$7) -> #DIV/0! | O11: =PEARSON($B11:$F11,Y$3:Y$7) -> #DIV/0! | P11: =PEARSON($B11:$F11,Z$3:Z$7) -> #DIV/0! | Q11: =PEARSON($B11:$F11,AA$3:AA$7) -> #DIV/0! | R11: =PEARSON($B11:$F11,AB$3:AB$7) -> #DIV/0! | S11: CC019 | T11: 4.4745193 | U11: 0.91842113 | V11: 5.6326012 | W11: 0.93238515 | X11: 2.1862349 | Y11: 13.18654 | Z11: 7.6177346 | AA11: 22.224783 | AB11: 13.18654
A12: Eye | B12: =B6C3F1!H12 -> 5.745 | C12: ='BALB cByJ'!I11 -> 1.6666667 | D12: =CBA!I11 -> 12.5 | E12: ='C3H'!I11 -> 1.75 | F12: ='C57BL6J'!I11 -> 1.25 | G12: 0 | H12: 0 | J12: =PEARSON($B12:$F12,T$3:T$7) -> -0.018408607 | K12: =PEARSON($B12:$F12,U$3:U$7) -> -0.15450775 | L12: =PEARSON($B12:$F12,V$3:V$7) -> 0.19926864 | M12: =PEARSON($B12:$F12,W$3:W$7) -> -0.37935345 | N12: =PEARSON($B12:$F12,X$3:X$7) -> 0.4432615 | O12: =PEARSON($B12:$F12,Y$3:Y$7) -> -0.12534046 | P12: =PEARSON($B12:$F12,Z$3:Z$7) -> -0.86150214 | Q12: =PEARSON($B12:$F12,AA$3:AA$7) -> -0.48764627 | R12: =PEARSON($B12:$F12,AB$3:AB$7) -> -0.12534046 | S12: CC032 | T12: 8.9022579 | U12: 0.91376366 | V12: 6.0399521 | W12: 0.91337873 | X12: 3.5157899 | Y12: 10.433571 | Z12: 4.4387625 | AA12: 29.749116 | AB12: 10.433571
A13: Forestomach | B13: =B6C3F1!H13 -> 2.0833333 | C13: ='BALB cByJ'!I12 -> 0 | D13: =CBA!I12 -> 2 | E13: ='C3H'!I12 -> #DIV/0! | F13: ='C57BL6J'!I12 -> 1.6666667 | G13: 0 | H13: 0 | J13: =PEARSON($B13:$F13,T$3:T$7) -> #DIV/0! | K13: =PEARSON($B13:$F13,U$3:U$7) -> #DIV/0! | L13: =PEARSON($B13:$F13,V$3:V$7) -> #DIV/0! | M13: =PEARSON($B13:$F13,W$3:W$7) -> #DIV/0! | N13: =PEARSON($B13:$F13,X$3:X$7) -> #DIV/0! | O13: =PEARSON($B13:$F13,Y$3:Y$7) -> #DIV/0! | P13: =PEARSON($B13:$F13,Z$3:Z$7) -> #DIV/0! | Q13: =PEARSON($B13:$F13,AA$3:AA$7) -> #DIV/0! | R13: =PEARSON($B13:$F13,AB$3:AB$7) -> #DIV/0! | S13: CC037 | T13: 4.3812192 | U13: 0.87366946 | V13: 7.069655 | W13: 0.87461235 | X13: 2.4594588 | Y13: 10.595603 | Z13: 4.0301495 | AA13: 20.830372 | AB13: 10.595603
A14: Gallbladder adenoma | B14: =B6C3F1!H14 -> 1 | C14: ='BALB cByJ'!I13 -> #DIV/0! | D14: =CBA!I13 -> #DIV/0! | E14: ='C3H'!I13 -> #DIV/0! | F14: ='C57BL6J'!I13 -> #DIV/0! | G14: 0 | H14: 0 | J14: =PEARSON($B14:$F14,T$3:T$7) -> #DIV/0! | K14: =PEARSON($B14:$F14,U$3:U$7) -> #DIV/0! | L14: =PEARSON($B14:$F14,V$3:V$7) -> #DIV/0! | M14: =PEARSON($B14:$F14,W$3:W$7) -> #DIV/0! | N14: =PEARSON($B14:$F14,X$3:X$7) -> #DIV/0! | O14: =PEARSON($B14:$F14,Y$3:Y$7) -> #DIV/0! | P14: =PEARSON($B14:$F14,Z$3:Z$7) -> #DIV/0! | Q14: =PEARSON($B14:$F14,AA$3:AA$7) -> #DIV/0! | R14: =PEARSON($B14:$F14,AB$3:AB$7) -> #DIV/0! | S14: CC040 | T14: 5.5489078 | U14: 0.88819077 | V14: 5.3096926 | W14: 0.90207796 | X14: 2.1468568 | Y14: 8.4612111 | Z14: 4.8774591 | AA14: 22.592092 | AB14: 8.4612111
A15: Gastrointestinal tract tumor | B15: =B6C3F1!H15 -> 0 | C15: ='BALB cByJ'!I14 -> #DIV/0! | D15: =CBA!I14 -> #DIV/0! | E15: ='C3H'!I14 -> #DIV/0! | F15: ='C57BL6J'!I14 -> #DIV/0! | G15: 0 | H15: 0 | J15: =PEARSON($B15:$F15,T$3:T$7) -> #DIV/0! | K15: =PEARSON($B15:$F15,U$3:U$7) -> #DIV/0! | L15: =PEARSON($B15:$F15,V$3:V$7) -> #DIV/0! | M15: =PEARSON($B15:$F15,W$3:W$7) -> #DIV/0! | N15: =PEARSON($B15:$F15,X$3:X$7) -> #DIV/0! | O15: =PEARSON($B15:$F15,Y$3:Y$7) -> #DIV/0! | P15: =PEARSON($B15:$F15,Z$3:Z$7) -> #DIV/0! | Q15: =PEARSON($B15:$F15,AA$3:AA$7) -> #DIV/0! | R15: =PEARSON($B15:$F15,AB$3:AB$7) -> #DIV/0! | S15: CC042 | T15: 5.585759 | U15: 0.88437859 | V15: 6.0683044 | W15: 0.87589373 | X15: 2.3337506 | Y15: 9.520079 | Z15: 4.4026524 | AA15: 24.04598 | AB15: 9.520079
A16: Heart hyperplasia - endothelial | B16: =B6C3F1!H16 -> 0 | C16: ='BALB cByJ'!I15 -> #DIV/0! | D16: =CBA!I15 -> #DIV/0! | E16: ='C3H'!I15 -> #DIV/0! | F16: ='C57BL6J'!I15 -> #DIV/0! | G16: 0 | H16: 0 | J16: =PEARSON($B16:$F16,T$3:T$7) -> #DIV/0! | K16: =PEARSON($B16:$F16,U$3:U$7) -> #DIV/0! | L16: =PEARSON($B16:$F16,V$3:V$7) -> #DIV/0! | M16: =PEARSON($B16:$F16,W$3:W$7) -> #DIV/0! | N16: =PEARSON($B16:$F16,X$3:X$7) -> #DIV/0! | O16: =PEARSON($B16:$F16,Y$3:Y$7) -> #DIV/0! | P16: =PEARSON($B16:$F16,Z$3:Z$7) -> #DIV/0! | Q16: =PEARSON($B16:$F16,AA$3:AA$7) -> #DIV/0! | R16: =PEARSON($B16:$F16,AB$3:AB$7) -> #DIV/0! | S16: CC051 | T16: 5.7273693 | U16: 0.91167249 | V16: 6.2942192 | W16: 0.90868826 | X16: 2.2512032 | Y16: 10.441242 | Z16: 5.3569471 | AA16: 24.291689 | AB16: 10.441242
A17: Intestine | B17: =B6C3F1!H17 -> 1.625 | C17: ='BALB cByJ'!I16 -> 0.234375 | D17: =CBA!I16 -> #DIV/0! | E17: ='C3H'!I16 -> #DIV/0! | F17: ='C57BL6J'!I16 -> 0.25925926 | G17: 0 | H17: 0 | J17: =PEARSON($B17:$F17,T$3:T$7) -> #DIV/0! | K17: =PEARSON($B17:$F17,U$3:U$7) -> #DIV/0! | L17: =PEARSON($B17:$F17,V$3:V$7) -> #DIV/0! | M17: =PEARSON($B17:$F17,W$3:W$7) -> #DIV/0! | N17: =PEARSON($B17:$F17,X$3:X$7) -> #DIV/0! | O17: =PEARSON($B17:$F17,Y$3:Y$7) -> #DIV/0! | P17: =PEARSON($B17:$F17,Z$3:Z$7) -> #DIV/0! | Q17: =PEARSON($B17:$F17,AA$3:AA$7) -> #DIV/0! | R17: =PEARSON($B17:$F17,AB$3:AB$7) -> #DIV/0! | S17: CC061 | T17: 5.1274601 | U17: 0.88178371 | V17: 5.8920583 | W17: 0.89578155 | X17: 2.6616121 | Y17: 9.6199854 | Z17: 3.8530935 | AA17: 36.582015 | AB17: 9.6199854
A18: Kidney | B18: =B6C3F1!H18 -> 0.75 | C18: ='BALB cByJ'!I17 -> 0 | D18: =CBA!I17 -> 2.05 | E18: ='C3H'!I17 -> #DIV/0! | F18: ='C57BL6J'!I17 -> 2.4111111 | G18: 0 | H18: 0 | J18: =PEARSON($B18:$F18,T$3:T$7) -> #DIV/0! | K18: =PEARSON($B18:$F18,U$3:U$7) -> #DIV/0! | L18: =PEARSON($B18:$F18,V$3:V$7) -> #DIV/0! | M18: =PEARSON($B18:$F18,W$3:W$7) -> #DIV/0! | N18: =PEARSON($B18:$F18,X$3:X$7) -> #DIV/0! | O18: =PEARSON($B18:$F18,Y$3:Y$7) -> #DIV/0! | P18: =PEARSON($B18:$F18,Z$3:Z$7) -> #DIV/0! | Q18: =PEARSON($B18:$F18,AA$3:AA$7) -> #DIV/0! | R18: =PEARSON($B18:$F18,AB$3:AB$7) -> #DIV/0!
A19: Leukocyte | B19: =B6C3F1!H19 -> 2.93125 | C19: ='BALB cByJ'!I18 -> 3 | D19: =CBA!I18 -> 4.8333333 | E19: ='C3H'!I18 -> 2.846 | F19: ='C57BL6J'!I18 -> 6.7793103 | G19: 0 | H19: 0 | J19: =PEARSON($B19:$F19,T$3:T$7) -> -0.44670648 | K19: =PEARSON($B19:$F19,U$3:U$7) -> -0.40519547 | L19: =PEARSON($B19:$F19,V$3:V$7) -> -0.20493061 | M19: =PEARSON($B19:$F19,W$3:W$7) -> -0.25301993 | N19: =PEARSON($B19:$F19,X$3:X$7) -> -0.25842333 | O19: =PEARSON($B19:$F19,Y$3:Y$7) -> -0.5036574 | P19: =PEARSON($B19:$F19,Z$3:Z$7) -> -0.48392606 | Q19: =PEARSON($B19:$F19,AA$3:AA$7) -> -0.43364915 | R19: =PEARSON($B19:$F19,AB$3:AB$7) -> -0.5036574
A20: Liver | B20: =B6C3F1!H20 -> 13.157895 | C20: ='BALB cByJ'!I19 -> 2.5 | D20: =CBA!I19 -> 24.53 | E20: ='C3H'!I19 -> 24.4125 | F20: ='C57BL6J'!I19 -> 2.2847222 | G20: 0 | H20: 0 | J20: =PEARSON($B20:$F20,T$3:T$7) -> -0.076181205 | K20: =PEARSON($B20:$F20,U$3:U$7) -> -0.53601846 | L20: =PEARSON($B20:$F20,V$3:V$7) -> 0.66545127 | M20: =PEARSON($B20:$F20,W$3:W$7) -> -0.44589806 | N20: =PEARSON($B20:$F20,X$3:X$7) -> 0.30125311 | O20: =PEARSON($B20:$F20,Y$3:Y$7) -> 0.58841096 | P20: =PEARSON($B20:$F20,Z$3:Z$7) -> -0.16670595 | Q20: =PEARSON($B20:$F20,AA$3:AA$7) -> 0.18136345 | R20: =PEARSON($B20:$F20,AB$3:AB$7) -> 0.58841096
A21: Lung | B21: =B6C3F1!H21 -> 9.3 | C21: ='BALB cByJ'!I20 -> 4.375 | D21: =CBA!I20 -> 5.5 | E21: ='C3H'!I20 -> 4.1666667 | F21: ='C57BL6J'!I20 -> 3.2857143 | G21: 0 | H21: 0 | J21: =PEARSON($B21:$F21,T$3:T$7) -> -0.29364712 | K21: =PEARSON($B21:$F21,U$3:U$7) -> 0.065891217 | L21: =PEARSON($B21:$F21,V$3:V$7) -> -0.49480946 | M21: =PEARSON($B21:$F21,W$3:W$7) -> -0.48773356 | N21: =PEARSON($B21:$F21,X$3:X$7) -> 0.94814712 | O21: =PEARSON($B21:$F21,Y$3:Y$7) -> -0.38202795 | P21: =PEARSON($B21:$F21,Z$3:Z$7) -> -0.19146731 | Q21: =PEARSON($B21:$F21,AA$3:AA$7) -> -0.58357784 | R21: =PEARSON($B21:$F21,AB$3:AB$7) -> -0.38202795
A22: Lymphoid tissue lymphoma | B22: =B6C3F1!H22 -> 14 | C22: ='BALB cByJ'!I21 -> #DIV/0! | D22: =CBA!I21 -> #DIV/0! | E22: ='C3H'!I21 -> #DIV/0! | F22: ='C57BL6J'!I21 -> #DIV/0! | G22: 0 | H22: 0 | J22: =PEARSON($B22:$F22,T$3:T$7) -> #DIV/0! | K22: =PEARSON($B22:$F22,U$3:U$7) -> #DIV/0! | L22: =PEARSON($B22:$F22,V$3:V$7) -> #DIV/0! | M22: =PEARSON($B22:$F22,W$3:W$7) -> #DIV/0! | N22: =PEARSON($B22:$F22,X$3:X$7) -> #DIV/0! | O22: =PEARSON($B22:$F22,Y$3:Y$7) -> #DIV/0! | P22: =PEARSON($B22:$F22,Z$3:Z$7) -> #DIV/0! | Q22: =PEARSON($B22:$F22,AA$3:AA$7) -> #DIV/0! | R22: =PEARSON($B22:$F22,AB$3:AB$7) -> #DIV/0!
A23: Mammary gland | B23: =B6C3F1!H23 -> 1.4 | C23: ='BALB cByJ'!I22 -> 2.2916667 | D23: =CBA!I22 -> 34.875 | E23: ='C3H'!I22 -> 67.1 | F23: ='C57BL6J'!I22 -> 0.7 | G23: 0 | H23: 0 | J23: =PEARSON($B23:$F23,T$3:T$7) -> 0.083864257 | K23: =PEARSON($B23:$F23,U$3:U$7) -> -0.51306457 | L23: =PEARSON($B23:$F23,V$3:V$7) -> 0.86908765 | M23: =PEARSON($B23:$F23,W$3:W$7) -> -0.14339898 | N23: =PEARSON($B23:$F23,X$3:X$7) -> -0.15622033 | O23: =PEARSON($B23:$F23,Y$3:Y$7) -> 0.8851461 | P23: =PEARSON($B23:$F23,Z$3:Z$7) -> 0.23750325 | Q23: =PEARSON($B23:$F23,AA$3:AA$7) -> 0.6339354 | R23: =PEARSON($B23:$F23,AB$3:AB$7) -> 0.8851461
A24: Mesodermal cell | B24: =B6C3F1!H24 -> 1.2809524 | C24: ='BALB cByJ'!I23 -> #DIV/0! | D24: =CBA!I23 -> 1.75 | E24: ='C3H'!I23 -> 1.25 | F24: ='C57BL6J'!I23 -> 1.8545455 | G24: 0 | H24: 0 | J24: =PEARSON($B24:$F24,T$3:T$7) -> #DIV/0! | K24: =PEARSON($B24:$F24,U$3:U$7) -> #DIV/0! | L24: =PEARSON($B24:$F24,V$3:V$7) -> #DIV/0! | M24: =PEARSON($B24:$F24,W$3:W$7) -> #DIV/0! | N24: =PEARSON($B24:$F24,X$3:X$7) -> #DIV/0! | O24: =PEARSON($B24:$F24,Y$3:Y$7) -> #DIV/0! | P24: =PEARSON($B24:$F24,Z$3:Z$7) -> #DIV/0! | Q24: =PEARSON($B24:$F24,AA$3:AA$7) -> #DIV/0! | R24: =PEARSON($B24:$F24,AB$3:AB$7) -> #DIV/0!
A25: Mesothelium mesothelioma | B25: =B6C3F1!H25 -> 0.275 | C25: ='BALB cByJ'!I24 -> #DIV/0! | D25: =CBA!I24 -> #DIV/0! | E25: ='C3H'!I24 -> #DIV/0! | F25: ='C57BL6J'!I24 -> #DIV/0! | G25: 0 | H25: 0 | J25: =PEARSON($B25:$F25,T$3:T$7) -> #DIV/0! | K25: =PEARSON($B25:$F25,U$3:U$7) -> #DIV/0! | L25: =PEARSON($B25:$F25,V$3:V$7) -> #DIV/0! | M25: =PEARSON($B25:$F25,W$3:W$7) -> #DIV/0! | N25: =PEARSON($B25:$F25,X$3:X$7) -> #DIV/0! | O25: =PEARSON($B25:$F25,Y$3:Y$7) -> #DIV/0! | P25: =PEARSON($B25:$F25,Z$3:Z$7) -> #DIV/0! | Q25: =PEARSON($B25:$F25,AA$3:AA$7) -> #DIV/0! | R25: =PEARSON($B25:$F25,AB$3:AB$7) -> #DIV/0!
A26: Muscle | B26: =B6C3F1!H26 -> 0.86363636 | C26: ='BALB cByJ'!I25 -> 2.1 | D26: =CBA!I25 -> #DIV/0! | E26: ='C3H'!I25 -> #DIV/0! | F26: ='C57BL6J'!I25 -> 0.92857143 | G26: 0 | H26: 0 | J26: =PEARSON($B26:$F26,T$3:T$7) -> #DIV/0! | K26: =PEARSON($B26:$F26,U$3:U$7) -> #DIV/0! | L26: =PEARSON($B26:$F26,V$3:V$7) -> #DIV/0! | M26: =PEARSON($B26:$F26,W$3:W$7) -> #DIV/0! | N26: =PEARSON($B26:$F26,X$3:X$7) -> #DIV/0! | O26: =PEARSON($B26:$F26,Y$3:Y$7) -> #DIV/0! | P26: =PEARSON($B26:$F26,Z$3:Z$7) -> #DIV/0! | Q26: =PEARSON($B26:$F26,AA$3:AA$7) -> #DIV/0! | R26: =PEARSON($B26:$F26,AB$3:AB$7) -> #DIV/0!
A27: Nose | B27: =B6C3F1!H27 -> 1 | C27: ='BALB cByJ'!I26 -> 2.5 | D27: =CBA!I26 -> #DIV/0! | E27: ='C3H'!I26 -> #DIV/0! | F27: ='C57BL6J'!I26 -> #DIV/0! | G27: 0 | H27: 0 | J27: =PEARSON($B27:$F27,T$3:T$7) -> #DIV/0! | K27: =PEARSON($B27:$F27,U$3:U$7) -> #DIV/0! | L27: =PEARSON($B27:$F27,V$3:V$7) -> #DIV/0! | M27: =PEARSON($B27:$F27,W$3:W$7) -> #DIV/0! | N27: =PEARSON($B27:$F27,X$3:X$7) -> #DIV/0! | O27: =PEARSON($B27:$F27,Y$3:Y$7) -> #DIV/0! | P27: =PEARSON($B27:$F27,Z$3:Z$7) -> #DIV/0! | Q27: =PEARSON($B27:$F27,AA$3:AA$7) -> #DIV/0! | R27: =PEARSON($B27:$F27,AB$3:AB$7) -> #DIV/0!
A28: Oral cavity squamous cell | B28: =B6C3F1!H28 -> 1 | C28: ='BALB cByJ'!I27 -> #DIV/0! | D28: =CBA!I27 -> #DIV/0! | E28: ='C3H'!I27 -> #DIV/0! | F28: ='C57BL6J'!I27 -> #DIV/0! | G28: 0 | H28: 0 | J28: =PEARSON($B28:$F28,T$3:T$7) -> #DIV/0! | K28: =PEARSON($B28:$F28,U$3:U$7) -> #DIV/0! | L28: =PEARSON($B28:$F28,V$3:V$7) -> #DIV/0! | M28: =PEARSON($B28:$F28,W$3:W$7) -> #DIV/0! | N28: =PEARSON($B28:$F28,X$3:X$7) -> #DIV/0! | O28: =PEARSON($B28:$F28,Y$3:Y$7) -> #DIV/0! | P28: =PEARSON($B28:$F28,Z$3:Z$7) -> #DIV/0! | Q28: =PEARSON($B28:$F28,AA$3:AA$7) -> #DIV/0! | R28: =PEARSON($B28:$F28,AB$3:AB$7) -> #DIV/0!
A29: Ovary | B29: =B6C3F1!H29 -> 1.1533333 | C29: ='BALB cByJ'!I28 -> 14.5 | D29: =CBA!I28 -> 1.7888889 | E29: ='C3H'!I28 -> 10.75 | F29: ='C57BL6J'!I28 -> 2.0357143 | G29: 0 | H29: 0 | J29: =PEARSON($B29:$F29,T$3:T$7) -> 0.80286533 | K29: =PEARSON($B29:$F29,U$3:U$7) -> 0.57983096 | L29: =PEARSON($B29:$F29,V$3:V$7) -> 0.46099651 | M29: =PEARSON($B29:$F29,W$3:W$7) -> 0.85755231 | N29: =PEARSON($B29:$F29,X$3:X$7) -> -0.65091541 | O29: =PEARSON($B29:$F29,Y$3:Y$7) -> 0.66586754 | P29: =PEARSON($B29:$F29,Z$3:Z$7) -> 0.64532698 | Q29: =PEARSON($B29:$F29,AA$3:AA$7) -> 0.88048038 | R29: =PEARSON($B29:$F29,AB$3:AB$7) -> 0.66586754
... A38: Skin | B38: =B6C3F1!H38 -> 0.915 | C38: ='BALB cByJ'!I37 -> 0.3125 | D38: =CBA!I37 -> 0 | E38: ='C3H'!I37 -> #DIV/0! | F38: ='C57BL6J'!I37 -> 1.5333333 | G38: 0 | H38: 0 | J38: =PEARSON($B38:$F38,T$3:T$7) -> #DIV/0! | K38: =PEARSON($B38:$F38,U$3:U$7) -> #DIV/0! | L38: =PEARSON($B38:$F38,V$3:V$7) -> #DIV/0! | M38: =PEARSON($B38:$F38,W$3:W$7) -> #DIV/0! | N38: =PEARSON($B38:$F38,X$3:X$7) -> #DIV/0! | O38: =PEARSON($B38:$F38,Y$3:Y$7) -> #DIV/0! | P38: =PEARSON($B38:$F38,Z$3:Z$7) -> #DIV/0! | Q38: =PEARSON($B38:$F38,AA$3:AA$7) -> #DIV/0! | R38: =PEARSON($B38:$F38,AB$3:AB$7) -> #DIV/0!
A39: Splenic lymphoma | G39: 0 | H39: 0
A40: Stomach - Glandular | B40: =B6C3F1!H39 -> 1 | C40: ='BALB cByJ'!I38 -> 2.8125 | D40: =CBA!I38 -> #DIV/0! | E40: ='C3H'!I38 -> #DIV/0! | F40: ='C57BL6J'!I38 -> 2.8 | G40: 0 | H40: 0 | J40: =PEARSON($B40:$F40,T$3:T$7) -> #DIV/0! | K40: =PEARSON($B40:$F40,U$3:U$7) -> #DIV/0! | L40: =PEARSON($B40:$F40,V$3:V$7) -> #DIV/0! | M40: =PEARSON($B40:$F40,W$3:W$7) -> #DIV/0! | N40: =PEARSON($B40:$F40,X$3:X$7) -> #DIV/0! | O40: =PEARSON($B40:$F40,Y$3:Y$7) -> #DIV/0! | P40: =PEARSON($B40:$F40,Z$3:Z$7) -> #DIV/0! | Q40: =PEARSON($B40:$F40,AA$3:AA$7) -> #DIV/0! | R40: =PEARSON($B40:$F40,AB$3:AB$7) -> #DIV/0!
A41: Testis | B41: =B6C3F1!H40 -> 1.1333333 | C41: ='BALB cByJ'!I39 -> 0.83333333 | D41: =CBA!I39 -> #DIV/0! | E41: ='C3H'!I39 -> #DIV/0! | F41: ='C57BL6J'!I39 -> 1 | G41: 0 | H41: 0 | J41: =PEARSON($B41:$F41,T$3:T$7) -> #DIV/0! | K41: =PEARSON($B41:$F41,U$3:U$7) -> #DIV/0! | L41: =PEARSON($B41:$F41,V$3:V$7) -> #DIV/0! | M41: =PEARSON($B41:$F41,W$3:W$7) -> #DIV/0! | N41: =PEARSON($B41:$F41,X$3:X$7) -> #DIV/0! | O41: =PEARSON($B41:$F41,Y$3:Y$7) -> #DIV/0! | P41: =PEARSON($B41:$F41,Z$3:Z$7) -> #DIV/0! | Q41: =PEARSON($B41:$F41,AA$3:AA$7) -> #DIV/0! | R41: =PEARSON($B41:$F41,AB$3:AB$7) -> #DIV/0!
A42: Thymus lymphoma | G42: 0 | H42: 0 | I42: ~38%
A43: Thymus thymoma | B43: =B6C3F1!H41 -> 1.5 | C43: ='BALB cByJ'!I40 -> #DIV/0! | D43: =CBA!I40 -> #DIV/0! | E43: ='C3H'!I40 -> #DIV/0! | F43: ='C57BL6J'!I40 -> #DIV/0! | G43: 0 | H43: 0 | J43: =PEARSON($B43:$F43,T$3:T$7) -> #DIV/0! | K43: =PEARSON($B43:$F43,U$3:U$7) -> #DIV/0! | L43: =PEARSON($B43:$F43,V$3:V$7) -> #DIV/0! | M43: =PEARSON($B43:$F43,W$3:W$7) -> #DIV/0! | N43: =PEARSON($B43:$F43,X$3:X$7) -> #DIV/0! | O43: =PEARSON($B43:$F43,Y$3:Y$7) -> #DIV/0! | P43: =PEARSON($B43:$F43,Z$3:Z$7) -> #DIV/0! | Q43: =PEARSON($B43:$F43,AA$3:AA$7) -> #DIV/0! | R43: =PEARSON($B43:$F43,AB$3:AB$7) -> #DIV/0!
A44: Thyroid gland | B44: =B6C3F1!H42 -> 2.5 | C44: ='BALB cByJ'!I41 -> 3.75 | D44: =CBA!I41 -> 16.666667 | E44: ='C3H'!I41 -> #DIV/0! | F44: ='C57BL6J'!I41 -> 3 | G44: 0 | H44: 0 | J44: =PEARSON($B44:$F44,T$3:T$7) -> #DIV/0! | K44: =PEARSON($B44:$F44,U$3:U$7) -> #DIV/0! | L44: =PEARSON($B44:$F44,V$3:V$7) -> #DIV/0! | M44: =PEARSON($B44:$F44,W$3:W$7) -> #DIV/0! | N44: =PEARSON($B44:$F44,X$3:X$7) -> #DIV/0! | O44: =PEARSON($B44:$F44,Y$3:Y$7) -> #DIV/0! | P44: =PEARSON($B44:$F44,Z$3:Z$7) -> #DIV/0! | Q44: =PEARSON($B44:$F44,AA$3:AA$7) -> #DIV/0! | R44: =PEARSON($B44:$F44,AB$3:AB$7) -> #DIV/0!
A45: Tooth odontoma | B45: =B6C3F1!H43 -> 2 | C45: ='BALB cByJ'!I42 -> #DIV/0! | D45: =CBA!I42 -> #DIV/0! | E45: ='C3H'!I42 -> #DIV/0! | F45: ='C57BL6J'!I42 -> #DIV/0! | G45: 0 | H45: 0 | J45: =PEARSON($B45:$F45,T$3:T$7) -> #DIV/0! | K45: =PEARSON($B45:$F45,U$3:U$7) -> #DIV/0! | L45: =PEARSON($B45:$F45,V$3:V$7) -> #DIV/0! | M45: =PEARSON($B45:$F45,W$3:W$7) -> #DIV/0! | N45: =PEARSON($B45:$F45,X$3:X$7) -> #DIV/0! | O45: =PEARSON($B45:$F45,Y$3:Y$7) -> #DIV/0! | P45: =PEARSON($B45:$F45,Z$3:Z$7) -> #DIV/0! | Q45: =PEARSON($B45:$F45,AA$3:AA$7) -> #DIV/0! | R45: =PEARSON($B45:$F45,AB$3:AB$7) -> #DIV/0!
A46: Urinary bladder papilloma | B46: =B6C3F1!H44 -> 1 | C46: ='BALB cByJ'!I43 -> #DIV/0! | D46: =CBA!I43 -> #DIV/0! | E46: ='C3H'!I43 -> #DIV/0! | F46: ='C57BL6J'!I43 -> #DIV/0! | G46: 0 | H46: 0 | J46: =PEARSON($B46:$F46,T$3:T$7) -> #DIV/0! | K46: =PEARSON($B46:$F46,U$3:U$7) -> #DIV/0! | L46: =PEARSON($B46:$F46,V$3:V$7) -> #DIV/0! | M46: =PEARSON($B46:$F46,W$3:W$7) -> #DIV/0! | N46: =PEARSON($B46:$F46,X$3:X$7) -> #DIV/0! | O46: =PEARSON($B46:$F46,Y$3:Y$7) -> #DIV/0! | P46: =PEARSON($B46:$F46,Z$3:Z$7) -> #DIV/0! | Q46: =PEARSON($B46:$F46,AA$3:AA$7) -> #DIV/0! | R46: =PEARSON($B46:$F46,AB$3:AB$7) -> #DIV/0!
A47: Uterus | B47: =B6C3F1!H45 -> 2 | C47: ='BALB cByJ'!I44 -> 1.875 | D47: =CBA!I44 -> 8.9444444 | E47: ='C3H'!I44 -> #DIV/0! | F47: ='C57BL6J'!I44 -> 5.5 | G47: 0 | H47: 0 | J47: =PEARSON($B47:$F47,T$3:T$7) -> #DIV/0! | K47: =PEARSON($B47:$F47,U$3:U$7) -> #DIV/0! | L47: =PEARSON($B47:$F47,V$3:V$7) -> #DIV/0! | M47: =PEARSON($B47:$F47,W$3:W$7) -> #DIV/0! | N47: =PEARSON($B47:$F47,X$3:X$7) -> #DIV/0! | O47: =PEARSON($B47:$F47,Y$3:Y$7) -> #DIV/0! | P47: =PEARSON($B47:$F47,Z$3:Z$7) -> #DIV/0! | Q47: =PEARSON($B47:$F47,AA$3:AA$7) -> #DIV/0! | R47: =PEARSON($B47:$F47,AB$3:AB$7) -> #DIV/0!
A48: Vagina squamous cell papilloma | B48: =B6C3F1!H46 -> 1 | C48: ='BALB cByJ'!I45 -> #DIV/0! | D48: =CBA!I45 -> #DIV/0! | E48: ='C3H'!I45 -> #DIV/0! | F48: ='C57BL6J'!I45 -> #DIV/0! | G48: 0 | H48: 0 | J48: =PEARSON($B48:$F48,T$3:T$7) -> #DIV/0! | K48: =PEARSON($B48:$F48,U$3:U$7) -> #DIV/0! | L48: =PEARSON($B48:$F48,V$3:V$7) -> #DIV/0! | M48: =PEARSON($B48:$F48,W$3:W$7) -> #DIV/0! | N48: =PEARSON($B48:$F48,X$3:X$7) -> #DIV/0! | O48: =PEARSON($B48:$F48,Y$3:Y$7) -> #DIV/0! | P48: =PEARSON($B48:$F48,Z$3:Z$7) -> #DIV/0! | Q48: =PEARSON($B48:$F48,AA$3:AA$7) -> #DIV/0! | R48: =PEARSON($B48:$F48,AB$3:AB$7) -> #DIV/0!

Sheet Summary_without C3H
B1: B6C3F1 | C1: BalbC/Jy | D1: CBA | E1: C57BL/6 | F1: Pearson HZE | G1: Pearson X | H1: Pearson background | M1: Pearson HZE | N1: Pearson X | O1: Pearson background | R1: 4 Strains | S1: P-value <0.05 for Pearson>0.955
A2: Adipose tissue lipoma | B2: =B6C3F1!H3 -> 0.75 | C2: ='BALB cByJ'!I2 -> 0 | D2: =CBA!I2 -> #DIV/0! | E2: ='C57BL6J'!I2 -> #DIV/0!
A3: Adrenal gland | B3: =B6C3F1!H4 -> 4.4285714 | C3: ='BALB cByJ'!I3 -> 4.1666667 | D3: =CBA!I3 -> 13.833333 | E3: ='C57BL6J'!I3 -> 3.09375 | F3: =PEARSON(B3:E3,$AA$12:$AA$15) -> 0.91119339 | G3: =PEARSON(B3:E3,$T$5:$T$8) -> 0.99302946 | H3: =PEARSON(B3:E3,$U$5:$U$8) -> 0.95862985 | I3: =PEARSON(B3:E3,$S$18:$S$21) -> -0.51926864 | J3: =PEARSON(B3:E3,$U$12:$U$15) -> 0.8539434 | M3: =IF(F3>0.955,"Signficant","No") -> No | N3: =IF(G3>0.955,"Signficant","No") -> Signficant | O3: =IF(H3>0.955,"Signficant","No") -> Signficant | S3: HZE-tau | T3: X-tau | U3: Bgd | V3: Old data
A4: Blood vessel | B4: =B6C3F1!H5 -> 1.6428571 | C4: ='BALB cByJ'!I4 -> 1.25 | D4: =CBA!I4 -> 0 | E4: ='C57BL6J'!I4 -> 1.75 | F4: =PEARSON(B4:E4,$AA$12:$AA$15) -> -0.9816589 | G4: =PEARSON(B4:E4,$T$5:$T$8) -> -0.96092825 | H4: =PEARSON(B4:E4,$U$5:$U$8) -> -0.99743539 | I4: =PEARSON(B4:E4,$S$18:$S$21) -> 0.64935433 | J4: =PEARSON(B4:E4,$U$12:$U$15) -> -0.94253877 | M4: =IF(F4>0.955,"Signficant","No") -> No | N4: =IF(G4>0.955,"Signficant","No") -> No | O4: =IF(H4>0.955,"Signficant","No") -> No
A5: Bone osteosarcoma | B5: =B6C3F1!H6 -> 2 | C5: ='BALB cByJ'!I5 -> #DIV/0! | D5: =CBA!I5 -> #DIV/0! | E5: ='C57BL6J'!I5 -> #DIV/0! | F5: =PEARSON(B5:E5,$AA$12:$AA$15) -> #DIV/0! | I5: =PEARSON(B5:E5,$S$18:$S$21) -> #DIV/0! | J5: =PEARSON(B5:E5,$U$12:$U$15) -> #DIV/0! | R5: B6C3 | S5: 11.250761 | T5: 3.93276 | U5: 0.3852915
A6: Clitoral gland | B6: =B6C3F1!H7 -> 0 | C6: ='BALB cByJ'!I6 -> 0 | D6: =CBA!I6 -> #DIV/0! | E6: ='C57BL6J'!I6 -> #DIV/0! | F6: =PEARSON(B6:E6,$AA$12:$AA$15) -> #DIV/0! | I6: =PEARSON(B6:E6,$S$18:$S$21) -> #DIV/0! | J6: =PEARSON(B6:E6,$U$12:$U$15) -> #DIV/0! | R6: BALBC | S6: 11.55611 | T6: 3.8970483 | U6: 0.4243104
A7: CNS - Brain | B7: =B6C3F1!H8 -> 0.625 | C7: ='BALB cByJ'!I7 -> 0 | D7: =CBA!I7 -> #DIV/0! | E7: ='C57BL6J'!I7 -> 0 | F7: =PEARSON(B7:E7,$AA$12:$AA$15) -> #DIV/0! | I7: =PEARSON(B7:E7,$S$18:$S$21) -> #DIV/0! | J7: =PEARSON(B7:E7,$U$12:$U$15) -> #DIV/0! | R7: CBA | S7: 13.130422 | T7: 4.254018 | U7: 0.514662
A8: Connective tissue | B8: =B6C3F1!H9 -> 3.4375 | C8: ='BALB cByJ'!I8 -> #DIV/0! | D8: =CBA!I8 -> #DIV/0! | E8: ='C57BL6J'!I8 -> 1.75 | F8: =PEARSON(B8:E8,$AA$12:$AA$15) -> #DIV/0! | I8: =PEARSON(B8:E8,$S$18:$S$21) -> #DIV/0! | J8: =PEARSON(B8:E8,$U$12:$U$15) -> #DIV/0! | R8: C57 | S8: 11.248485 | T8: 3.8284658 | U8: 0.386223
A9: Ear | B9: =B6C3F1!H10 -> 1 | C9: ='BALB cByJ'!I9 -> 0.625 | D9: =CBA!I9 -> #DIV/0! | E9: ='C57BL6J'!I9 -> 0 | F9: =PEARSON(B9:E9,$AA$12:$AA$15) -> #DIV/0! | I9: =PEARSON(B9:E9,$S$18:$S$21) -> #DIV/0! | J9: =PEARSON(B9:E9,$U$12:$U$15) -> #DIV/0!
A10: Esophagus squamous cell carcinoma | B10: =B6C3F1!H11 -> 1 | C10: ='BALB cByJ'!I10 -> #DIV/0! | D10: =CBA!I10 -> #DIV/0! | E10: ='C57BL6J'!I10 -> #DIV/0! | F10: =PEARSON(B10:E10,$AA$12:$AA$15) -> #DIV/0! | I10: =PEARSON(B10:E10,$S$18:$S$21) -> #DIV/0! | J10: =PEARSON(B10:E10,$U$12:$U$15) -> #DIV/0!
